Workbook

Sheet Student-Wise Result
A1: SEMESTER END EXAMINATION (SEE) – RESULT ANALYSIS
A2: Department: | C2: Academic Year: | F2: Semester:
A3: Programme: | D3: Branch: | G3: Class: | I3: Section:
A5: Sl.No | B5: Reg. No | C5: Student Name | D5: Course #1 | G5: Course #2 | J5: Course #3 | M5: Course #4 | P5: Course #5 | S5: Course #6 | V5: SGPA | W5: CGPA
D6: Grade | E6: Marks | F6: Credits | G6: Grade | H6: Marks | I6: Credits | J6: Grade | K6: Marks | L6: Credits | M6: Grade | N6: Marks | O6: Credits | P6: Grade | Q6: Marks | R6: Credits | S6: Grade | T6: Marks | U6: Credits
A7: Course Code → | D7: SUBJ1 | F7: 4 | G7: SUBJ2 | I7: 4 | J7: SUBJ3 | L7: 4 | M7: SUBJ4 | O7: 4 | P7: SUBJ5 | R7: 4 | S7: SUBJ6 | U7: 4
A8: Grade Points → | D8: O=10,A+=9,A=8,B+=7,B=6,C=5,P=4,F=0 | E8: Max 100 | F8: Credits | G8: O=10,A+=9,A=8,B+=7,B=6,C=5,P=4,F=0 | H8: Max 100 | I8: Credits | J8: O=10,A+=9,A=8,B+=7,B=6,C=5,P=4,F=0 | K8: Max 100 | L8: Credits | M8: O=10,A+=9,A=8,B+=7,B=6,C=5,P=4,F=0 | N8: Max 100 | O8: Credits | P8: O=10,A+=9,A=8,B+=7,B=6,C=5,P=4,F=0 | Q8: Max 100 | R8: Credits | S8: O=10,A+=9,A=8,B+=7,B=6,C=5,P=4,F=0 | T8: Max 100 | U8: Credits | V8: Auto | W8: Manual
A9: 1 | F9: =F7 -> 4 | I9: =I7 -> 4 | L9: =L7 -> 4 | O9: =O7 -> 4 | R9: =R7 -> 4 | U9: =U7 -> 4 | V9: =IFERROR(ROUND(((IFERROR(IF(D9="O",10,IF(D9="A+",9,IF(D9="A",8,IF(D9="B+",7,IF(D9="B",6,IF(D9="C",5,IF(D9="P",4,0))))))),0))*F9+(IFERROR(IF(G9="O",10,IF(G9="A+",9,IF(G9="A",8,IF(G9="B+",7,IF(G9="B",6,IF(G9="C",5,IF(G9="P",4,0))))))),0))*I9+(IFERROR(IF(J9="O",10,IF(J9="A+",9,IF(J9="A",8,IF(J9="B+",7,IF(J9="B",6,IF(J9="C",5,IF(J9="P",4,0))))))),0))*L9+(IFERROR(IF(M9="O",10,IF(M9="A+",9,IF(M9="A",8,IF(M9="B+",7,IF(M9="B",6,IF(M9="C",5,IF(M9="P",4,0))))))),0))*O9+(IFERROR(IF(P9="O",10,IF(P9="A+",9,IF(P9="A",8,IF(P9="B+",7,IF(P9="B",6,IF(P9="C",5,IF(P9="P",4,0))))))),0))*R9+(IFERROR(IF(S9="O",10,IF(S9="A+",9,IF(S9="A",8,IF(S9="B+",7,IF(S9="B",6,IF(S9="C",5,IF(S9="P",4,0))))))),0))*U9)/SUM(F9,I9,L9,O9,R9,U9),2),0) -> 0
A10: 2 | F10: =F7 -> 4 | I10: =I7 -> 4 | L10: =L7 -> 4 | O10: =O7 -> 4 | R10: =R7 -> 4 | U10: =U7 -> 4 | V10: =IFERROR(ROUND(((IFERROR(IF(D10="O",10,IF(D10="A+",9,IF(D10="A",8,IF(D10="B+",7,IF(D10="B",6,IF(D10="C",5,IF(D10="P",4,0))))))),0))*F10+(IFERROR(IF(G10="O",10,IF(G10="A+",9,IF(G10="A",8,IF(G10="B+",7,IF(G10="B",6,IF(G10="C",5,IF(G10="P",4,0))))))),0))*I10+(IFERROR(IF(J10="O",10,IF(J10="A+",9,IF(J10="A",8,IF(J10="B+",7,IF(J10="B",6,IF(J10="C",5,IF(J10="P",4,0))))))),0))*L10+(IFERROR(IF(M10="O",10,IF(M10="A+",9,IF(M10="A",8,IF(M10="B+",7,IF(M10="B",6,IF(M10="C",5,IF(M10="P",4,0))))))),0))*O10+(IFERROR(IF(P10="O",10,IF(P10="A+",9,IF(P10="A",8,IF(P10="B+",7,IF(P10="B",6,IF(P10="C",5,IF(P10="P",4,0))))))),0))*R10+(IFERROR(IF(S10="O",10,IF(S10="A+",9,IF(S10="A",8,IF(S10="B+",7,IF(S10="B",6,IF(S10="C",5,IF(S10="P",4,0))))))),0))*U10)/SUM(F10,I10,L10,O10,R10,U10),2),0) -> 0
A11: 3 | F11: =F7 -> 4 | I11: =I7 -> 4 | L11: =L7 -> 4 | O11: =O7 -> 4 | R11: =R7 -> 4 | U11: =U7 -> 4 | V11: =IFERROR(ROUND(((IFERROR(IF(D11="O",10,IF(D11="A+",9,IF(D11="A",8,IF(D11="B+",7,IF(D11="B",6,IF(D11="C",5,IF(D11="P",4,0))))))),0))*F11+(IFERROR(IF(G11="O",10,IF(G11="A+",9,IF(G11="A",8,IF(G11="B+",7,IF(G11="B",6,IF(G11="C",5,IF(G11="P",4,0))))))),0))*I11+(IFERROR(IF(J11="O",10,IF(J11="A+",9,IF(J11="A",8,IF(J11="B+",7,IF(J11="B",6,IF(J11="C",5,IF(J11="P",4,0))))))),0))*L11+(IFERROR(IF(M11="O",10,IF(M11="A+",9,IF(M11="A",8,IF(M11="B+",7,IF(M11="B",6,IF(M11="C",5,IF(M11="P",4,0))))))),0))*O11+(IFERROR(IF(P11="O",10,IF(P11="A+",9,IF(P11="A",8,IF(P11="B+",7,IF(P11="B",6,IF(P11="C",5,IF(P11="P",4,0))))))),0))*R11+(IFERROR(IF(S11="O",10,IF(S11="A+",9,IF(S11="A",8,IF(S11="B+",7,IF(S11="B",6,IF(S11="C",5,IF(S11="P",4,0))))))),0))*U11)/SUM(F11,I11,L11,O11,R11,U11),2),0) -> 0
A12: 4 | F12: =F7 -> 4 | I12: =I7 -> 4 | L12: =L7 -> 4 | O12: =O7 -> 4 | R12: =R7 -> 4 | U12: =U7 -> 4 | V12: =IFERROR(ROUND(((IFERROR(IF(D12="O",10,IF(D12="A+",9,IF(D12="A",8,IF(D12="B+",7,IF(D12="B",6,IF(D12="C",5,IF(D12="P",4,0))))))),0))*F12+(IFERROR(IF(G12="O",10,IF(G12="A+",9,IF(G12="A",8,IF(G12="B+",7,IF(G12="B",6,IF(G12="C",5,IF(G12="P",4,0))))))),0))*I12+(IFERROR(IF(J12="O",10,IF(J12="A+",9,IF(J12="A",8,IF(J12="B+",7,IF(J12="B",6,IF(J12="C",5,IF(J12="P",4,0))))))),0))*L12+(IFERROR(IF(M12="O",10,IF(M12="A+",9,IF(M12="A",8,IF(M12="B+",7,IF(M12="B",6,IF(M12="C",5,IF(M12="P",4,0))))))),0))*O12+(IFERROR(IF(P12="O",10,IF(P12="A+",9,IF(P12="A",8,IF(P12="B+",7,IF(P12="B",6,IF(P12="C",5,IF(P12="P",4,0))))))),0))*R12+(IFERROR(IF(S12="O",10,IF(S12="A+",9,IF(S12="A",8,IF(S12="B+",7,IF(S12="B",6,IF(S12="C",5,IF(S12="P",4,0))))))),0))*U12)/SUM(F12,I12,L12,O12,R12,U12),2),0) -> 0
A13: 5 | F13: =F7 -> 4 | I13: =I7 -> 4 | L13: =L7 -> 4 | O13: =O7 -> 4 | R13: =R7 -> 4 | U13: =U7 -> 4 | V13: =IFERROR(ROUND(((IFERROR(IF(D13="O",10,IF(D13="A+",9,IF(D13="A",8,IF(D13="B+",7,IF(D13="B",6,IF(D13="C",5,IF(D13="P",4,0))))))),0))*F13+(IFERROR(IF(G13="O",10,IF(G13="A+",9,IF(G13="A",8,IF(G13="B+",7,IF(G13="B",6,IF(G13="C",5,IF(G13="P",4,0))))))),0))*I13+(IFERROR(IF(J13="O",10,IF(J13="A+",9,IF(J13="A",8,IF(J13="B+",7,IF(J13="B",6,IF(J13="C",5,IF(J13="P",4,0))))))),0))*L13+(IFERROR(IF(M13="O",10,IF(M13="A+",9,IF(M13="A",8,IF(M13="B+",7,IF(M13="B",6,IF(M13="C",5,IF(M13="P",4,0))))))),0))*O13+(IFERROR(IF(P13="O",10,IF(P13="A+",9,IF(P13="A",8,IF(P13="B+",7,IF(P13="B",6,IF(P13="C",5,IF(P13="P",4,0))))))),0))*R13+(IFERROR(IF(S13="O",10,IF(S13="A+",9,IF(S13="A",8,IF(S13="B+",7,IF(S13="B",6,IF(S13="C",5,IF(S13="P",4,0))))))),0))*U13)/SUM(F13,I13,L13,O13,R13,U13),2),0) -> 0
A14: 6 | F14: =F7 -> 4 | I14: =I7 -> 4 | L14: =L7 -> 4 | O14: =O7 -> 4 | R14: =R7 -> 4 | U14: =U7 -> 4 | V14: =IFERROR(ROUND(((IFERROR(IF(D14="O",10,IF(D14="A+",9,IF(D14="A",8,IF(D14="B+",7,IF(D14="B",6,IF(D14="C",5,IF(D14="P",4,0))))))),0))*F14+(IFERROR(IF(G14="O",10,IF(G14="A+",9,IF(G14="A",8,IF(G14="B+",7,IF(G14="B",6,IF(G14="C",5,IF(G14="P",4,0))))))),0))*I14+(IFERROR(IF(J14="O",10,IF(J14="A+",9,IF(J14="A",8,IF(J14="B+",7,IF(J14="B",6,IF(J14="C",5,IF(J14="P",4,0))))))),0))*L14+(IFERROR(IF(M14="O",10,IF(M14="A+",9,IF(M14="A",8,IF(M14="B+",7,IF(M14="B",6,IF(M14="C",5,IF(M14="P",4,0))))))),0))*O14+(IFERROR(IF(P14="O",10,IF(P14="A+",9,IF(P14="A",8,IF(P14="B+",7,IF(P14="B",6,IF(P14="C",5,IF(P14="P",4,0))))))),0))*R14+(IFERROR(IF(S14="O",10,IF(S14="A+",9,IF(S14="A",8,IF(S14="B+",7,IF(S14="B",6,IF(S14="C",5,IF(S14="P",4,0))))))),0))*U14)/SUM(F14,I14,L14,O14,R14,U14),2),0) -> 0
A15: 7 | F15: =F7 -> 4 | I15: =I7 -> 4 | L15: =L7 -> 4 | O15: =O7 -> 4 | R15: =R7 -> 4 | U15: =U7 -> 4 | V15: =IFERROR(ROUND(((IFERROR(IF(D15="O",10,IF(D15="A+",9,IF(D15="A",8,IF(D15="B+",7,IF(D15="B",6,IF(D15="C",5,IF(D15="P",4,0))))))),0))*F15+(IFERROR(IF(G15="O",10,IF(G15="A+",9,IF(G15="A",8,IF(G15="B+",7,IF(G15="B",6,IF(G15="C",5,IF(G15="P",4,0))))))),0))*I15+(IFERROR(IF(J15="O",10,IF(J15="A+",9,IF(J15="A",8,IF(J15="B+",7,IF(J15="B",6,IF(J15="C",5,IF(J15="P",4,0))))))),0))*L15+(IFERROR(IF(M15="O",10,IF(M15="A+",9,IF(M15="A",8,IF(M15="B+",7,IF(M15="B",6,IF(M15="C",5,IF(M15="P",4,0))))))),0))*O15+(IFERROR(IF(P15="O",10,IF(P15="A+",9,IF(P15="A",8,IF(P15="B+",7,IF(P15="B",6,IF(P15="C",5,IF(P15="P",4,0))))))),0))*R15+(IFERROR(IF(S15="O",10,IF(S15="A+",9,IF(S15="A",8,IF(S15="B+",7,IF(S15="B",6,IF(S15="C",5,IF(S15="P",4,0))))))),0))*U15)/SUM(F15,I15,L15,O15,R15,U15),2),0) -> 0
A16: 8 | F16: =F7 -> 4 | I16: =I7 -> 4 | L16: =L7 -> 4 | O16: =O7 -> 4 | R16: =R7 -> 4 | U16: =U7 -> 4 | V16: =IFERROR(ROUND(((IFERROR(IF(D16="O",10,IF(D16="A+",9,IF(D16="A",8,IF(D16="B+",7,IF(D16="B",6,IF(D16="C",5,IF(D16="P",4,0))))))),0))*F16+(IFERROR(IF(G16="O",10,IF(G16="A+",9,IF(G16="A",8,IF(G16="B+",7,IF(G16="B",6,IF(G16="C",5,IF(G16="P",4,0))))))),0))*I16+(IFERROR(IF(J16="O",10,IF(J16="A+",9,IF(J16="A",8,IF(J16="B+",7,IF(J16="B",6,IF(J16="C",5,IF(J16="P",4,0))))))),0))*L16+(IFERROR(IF(M16="O",10,IF(M16="A+",9,IF(M16="A",8,IF(M16="B+",7,IF(M16="B",6,IF(M16="C",5,IF(M16="P",4,0))))))),0))*O16+(IFERROR(IF(P16="O",10,IF(P16="A+",9,IF(P16="A",8,IF(P16="B+",7,IF(P16="B",6,IF(P16="C",5,IF(P16="P",4,0))))))),0))*R16+(IFERROR(IF(S16="O",10,IF(S16="A+",9,IF(S16="A",8,IF(S16="B+",7,IF(S16="B",6,IF(S16="C",5,IF(S16="P",4,0))))))),0))*U16)/SUM(F16,I16,L16,O16,R16,U16),2),0) -> 0
A17: 9 | F17: =F7 -> 4 | I17: =I7 -> 4 | L17: =L7 -> 4 | O17: =O7 -> 4 | R17: =R7 -> 4 | U17: =U7 -> 4 | V17: =IFERROR(ROUND(((IFERROR(IF(D17="O",10,IF(D17="A+",9,IF(D17="A",8,IF(D17="B+",7,IF(D17="B",6,IF(D17="C",5,IF(D17="P",4,0))))))),0))*F17+(IFERROR(IF(G17="O",10,IF(G17="A+",9,IF(G17="A",8,IF(G17="B+",7,IF(G17="B",6,IF(G17="C",5,IF(G17="P",4,0))))))),0))*I17+(IFERROR(IF(J17="O",10,IF(J17="A+",9,IF(J17="A",8,IF(J17="B+",7,IF(J17="B",6,IF(J17="C",5,IF(J17="P",4,0))))))),0))*L17+(IFERROR(IF(M17="O",10,IF(M17="A+",9,IF(M17="A",8,IF(M17="B+",7,IF(M17="B",6,IF(M17="C",5,IF(M17="P",4,0))))))),0))*O17+(IFERROR(IF(P17="O",10,IF(P17="A+",9,IF(P17="A",8,IF(P17="B+",7,IF(P17="B",6,IF(P17="C",5,IF(P17="P",4,0))))))),0))*R17+(IFERROR(IF(S17="O",10,IF(S17="A+",9,IF(S17="A",8,IF(S17="B+",7,IF(S17="B",6,IF(S17="C",5,IF(S17="P",4,0))))))),0))*U17)/SUM(F17,I17,L17,O17,R17,U17),2),0) -> 0
A18: 10 | F18: =F7 -> 4 | I18: =I7 -> 4 | L18: =L7 -> 4 | O18: =O7 -> 4 | R18: =R7 -> 4 | U18: =U7 -> 4 | V18: =IFERROR(ROUND(((IFERROR(IF(D18="O",10,IF(D18="A+",9,IF(D18="A",8,IF(D18="B+",7,IF(D18="B",6,IF(D18="C",5,IF(D18="P",4,0))))))),0))*F18+(IFERROR(IF(G18="O",10,IF(G18="A+",9,IF(G18="A",8,IF(G18="B+",7,IF(G18="B",6,IF(G18="C",5,IF(G18="P",4,0))))))),0))*I18+(IFERROR(IF(J18="O",10,IF(J18="A+",9,IF(J18="A",8,IF(J18="B+",7,IF(J18="B",6,IF(J18="C",5,IF(J18="P",4,0))))))),0))*L18+(IFERROR(IF(M18="O",10,IF(M18="A+",9,IF(M18="A",8,IF(M18="B+",7,IF(M18="B",6,IF(M18="C",5,IF(M18="P",4,0))))))),0))*O18+(IFERROR(IF(P18="O",10,IF(P18="A+",9,IF(P18="A",8,IF(P18="B+",7,IF(P18="B",6,IF(P18="C",5,IF(P18="P",4,0))))))),0))*R18+(IFERROR(IF(S18="O",10,IF(S18="A+",9,IF(S18="A",8,IF(S18="B+",7,IF(S18="B",6,IF(S18="C",5,IF(S18="P",4,0))))))),0))*U18)/SUM(F18,I18,L18,O18,R18,U18),2),0) -> 0
A19: 11 | F19: =F7 -> 4 | I19: =I7 -> 4 | L19: =L7 -> 4 | O19: =O7 -> 4 | R19: =R7 -> 4 | U19: =U7 -> 4 | V19: =IFERROR(ROUND(((IFERROR(IF(D19="O",10,IF(D19="A+",9,IF(D19="A",8,IF(D19="B+",7,IF(D19="B",6,IF(D19="C",5,IF(D19="P",4,0))))))),0))*F19+(IFERROR(IF(G19="O",10,IF(G19="A+",9,IF(G19="A",8,IF(G19="B+",7,IF(G19="B",6,IF(G19="C",5,IF(G19="P",4,0))))))),0))*I19+(IFERROR(IF(J19="O",10,IF(J19="A+",9,IF(J19="A",8,IF(J19="B+",7,IF(J19="B",6,IF(J19="C",5,IF(J19="P",4,0))))))),0))*L19+(IFERROR(IF(M19="O",10,IF(M19="A+",9,IF(M19="A",8,IF(M19="B+",7,IF(M19="B",6,IF(M19="C",5,IF(M19="P",4,0))))))),0))*O19+(IFERROR(IF(P19="O",10,IF(P19="A+",9,IF(P19="A",8,IF(P19="B+",7,IF(P19="B",6,IF(P19="C",5,IF(P19="P",4,0))))))),0))*R19+(IFERROR(IF(S19="O",10,IF(S19="A+",9,IF(S19="A",8,IF(S19="B+",7,IF(S19="B",6,IF(S19="C",5,IF(S19="P",4,0))))))),0))*U19)/SUM(F19,I19,L19,O19,R19,U19),2),0) -> 0
A20: 12 | F20: =F7 -> 4 | I20: =I7 -> 4 | L20: =L7 -> 4 | O20: =O7 -> 4 | R20: =R7 -> 4 | U20: =U7 -> 4 | V20: =IFERROR(ROUND(((IFERROR(IF(D20="O",10,IF(D20="A+",9,IF(D20="A",8,IF(D20="B+",7,IF(D20="B",6,IF(D20="C",5,IF(D20="P",4,0))))))),0))*F20+(IFERROR(IF(G20="O",10,IF(G20="A+",9,IF(G20="A",8,IF(G20="B+",7,IF(G20="B",6,IF(G20="C",5,IF(G20="P",4,0))))))),0))*I20+(IFERROR(IF(J20="O",10,IF(J20="A+",9,IF(J20="A",8,IF(J20="B+",7,IF(J20="B",6,IF(J20="C",5,IF(J20="P",4,0))))))),0))*L20+(IFERROR(IF(M20="O",10,IF(M20="A+",9,IF(M20="A",8,IF(M20="B+",7,IF(M20="B",6,IF(M20="C",5,IF(M20="P",4,0))))))),0))*O20+(IFERROR(IF(P20="O",10,IF(P20="A+",9,IF(P20="A",8,IF(P20="B+",7,IF(P20="B",6,IF(P20="C",5,IF(P20="P",4,0))))))),0))*R20+(IFERROR(IF(S20="O",10,IF(S20="A+",9,IF(S20="A",8,IF(S20="B+",7,IF(S20="B",6,IF(S20="C",5,IF(S20="P",4,0))))))),0))*U20)/SUM(F20,I20,L20,O20,R20,U20),2),0) -> 0
A21: 13 | F21: =F7 -> 4 | I21: =I7 -> 4 | L21: =L7 -> 4 | O21: =O7 -> 4 | R21: =R7 -> 4 | U21: =U7 -> 4 | V21: =IFERROR(ROUND(((IFERROR(IF(D21="O",10,IF(D21="A+",9,IF(D21="A",8,IF(D21="B+",7,IF(D21="B",6,IF(D21="C",5,IF(D21="P",4,0))))))),0))*F21+(IFERROR(IF(G21="O",10,IF(G21="A+",9,IF(G21="A",8,IF(G21="B+",7,IF(G21="B",6,IF(G21="C",5,IF(G21="P",4,0))))))),0))*I21+(IFERROR(IF(J21="O",10,IF(J21="A+",9,IF(J21="A",8,IF(J21="B+",7,IF(J21="B",6,IF(J21="C",5,IF(J21="P",4,0))))))),0))*L21+(IFERROR(IF(M21="O",10,IF(M21="A+",9,IF(M21="A",8,IF(M21="B+",7,IF(M21="B",6,IF(M21="C",5,IF(M21="P",4,0))))))),0))*O21+(IFERROR(IF(P21="O",10,IF(P21="A+",9,IF(P21="A",8,IF(P21="B+",7,IF(P21="B",6,IF(P21="C",5,IF(P21="P",4,0))))))),0))*R21+(IFERROR(IF(S21="O",10,IF(S21="A+",9,IF(S21="A",8,IF(S21="B+",7,IF(S21="B",6,IF(S21="C",5,IF(S21="P",4,0))))))),0))*U21)/SUM(F21,I21,L21,O21,R21,U21),2),0) -> 0
A22: 14 | F22: =F7 -> 4 | I22: =I7 -> 4 | L22: =L7 -> 4 | O22: =O7 -> 4 | R22: =R7 -> 4 | U22: =U7 -> 4 | V22: =IFERROR(ROUND(((IFERROR(IF(D22="O",10,IF(D22="A+",9,IF(D22="A",8,IF(D22="B+",7,IF(D22="B",6,IF(D22="C",5,IF(D22="P",4,0))))))),0))*F22+(IFERROR(IF(G22="O",10,IF(G22="A+",9,IF(G22="A",8,IF(G22="B+",7,IF(G22="B",6,IF(G22="C",5,IF(G22="P",4,0))))))),0))*I22+(IFERROR(IF(J22="O",10,IF(J22="A+",9,IF(J22="A",8,IF(J22="B+",7,IF(J22="B",6,IF(J22="C",5,IF(J22="P",4,0))))))),0))*L22+(IFERROR(IF(M22="O",10,IF(M22="A+",9,IF(M22="A",8,IF(M22="B+",7,IF(M22="B",6,IF(M22="C",5,IF(M22="P",4,0))))))),0))*O22+(IFERROR(IF(P22="O",10,IF(P22="A+",9,IF(P22="A",8,IF(P22="B+",7,IF(P22="B",6,IF(P22="C",5,IF(P22="P",4,0))))))),0))*R22+(IFERROR(IF(S22="O",10,IF(S22="A+",9,IF(S22="A",8,IF(S22="B+",7,IF(S22="B",6,IF(S22="C",5,IF(S22="P",4,0))))))),0))*U22)/SUM(F22,I22,L22,O22,R22,U22),2),0) -> 0
A23: 15 | F23: =F7 -> 4 | I23: =I7 -> 4 | L23: =L7 -> 4 | O23: =O7 -> 4 | R23: =R7 -> 4 | U23: =U7 -> 4 | V23: =IFERROR(ROUND(((IFERROR(IF(D23="O",10,IF(D23="A+",9,IF(D23="A",8,IF(D23="B+",7,IF(D23="B",6,IF(D23="C",5,IF(D23="P",4,0))))))),0))*F23+(IFERROR(IF(G23="O",10,IF(G23="A+",9,IF(G23="A",8,IF(G23="B+",7,IF(G23="B",6,IF(G23="C",5,IF(G23="P",4,0))))))),0))*I23+(IFERROR(IF(J23="O",10,IF(J23="A+",9,IF(J23="A",8,IF(J23="B+",7,IF(J23="B",6,IF(J23="C",5,IF(J23="P",4,0))))))),0))*L23+(IFERROR(IF(M23="O",10,IF(M23="A+",9,IF(M23="A",8,IF(M23="B+",7,IF(M23="B",6,IF(M23="C",5,IF(M23="P",4,0))))))),0))*O23+(IFERROR(IF(P23="O",10,IF(P23="A+",9,IF(P23="A",8,IF(P23="B+",7,IF(P23="B",6,IF(P23="C",5,IF(P23="P",4,0))))))),0))*R23+(IFERROR(IF(S23="O",10,IF(S23="A+",9,IF(S23="A",8,IF(S23="B+",7,IF(S23="B",6,IF(S23="C",5,IF(S23="P",4,0))))))),0))*U23)/SUM(F23,I23,L23,O23,R23,U23),2),0) -> 0
A24: 16 | F24: =F7 -> 4 | I24: =I7 -> 4 | L24: =L7 -> 4 | O24: =O7 -> 4 | R24: =R7 -> 4 | U24: =U7 -> 4 | V24: =IFERROR(ROUND(((IFERROR(IF(D24="O",10,IF(D24="A+",9,IF(D24="A",8,IF(D24="B+",7,IF(D24="B",6,IF(D24="C",5,IF(D24="P",4,0))))))),0))*F24+(IFERROR(IF(G24="O",10,IF(G24="A+",9,IF(G24="A",8,IF(G24="B+",7,IF(G24="B",6,IF(G24="C",5,IF(G24="P",4,0))))))),0))*I24+(IFERROR(IF(J24="O",10,IF(J24="A+",9,IF(J24="A",8,IF(J24="B+",7,IF(J24="B",6,IF(J24="C",5,IF(J24="P",4,0))))))),0))*L24+(IFERROR(IF(M24="O",10,IF(M24="A+",9,IF(M24="A",8,IF(M24="B+",7,IF(M24="B",6,IF(M24="C",5,IF(M24="P",4,0))))))),0))*O24+(IFERROR(IF(P24="O",10,IF(P24="A+",9,IF(P24="A",8,IF(P24="B+",7,IF(P24="B",6,IF(P24="C",5,IF(P24="P",4,0))))))),0))*R24+(IFERROR(IF(S24="O",10,IF(S24="A+",9,IF(S24="A",8,IF(S24="B+",7,IF(S24="B",6,IF(S24="C",5,IF(S24="P",4,0))))))),0))*U24)/SUM(F24,I24,L24,O24,R24,U24),2),0) -> 0
A25: 17 | F25: =F7 -> 4 | I25: =I7 -> 4 | L25: =L7 -> 4 | O25: =O7 -> 4 | R25: =R7 -> 4 | U25: =U7 -> 4 | V25: =IFERROR(ROUND(((IFERROR(IF(D25="O",10,IF(D25="A+",9,IF(D25="A",8,IF(D25="B+",7,IF(D25="B",6,IF(D25="C",5,IF(D25="P",4,0))))))),0))*F25+(IFERROR(IF(G25="O",10,IF(G25="A+",9,IF(G25="A",8,IF(G25="B+",7,IF(G25="B",6,IF(G25="C",5,IF(G25="P",4,0))))))),0))*I25+(IFERROR(IF(J25="O",10,IF(J25="A+",9,IF(J25="A",8,IF(J25="B+",7,IF(J25="B",6,IF(J25="C",5,IF(J25="P",4,0))))))),0))*L25+(IFERROR(IF(M25="O",10,IF(M25="A+",9,IF(M25="A",8,IF(M25="B+",7,IF(M25="B",6,IF(M25="C",5,IF(M25="P",4,0))))))),0))*O25+(IFERROR(IF(P25="O",10,IF(P25="A+",9,IF(P25="A",8,IF(P25="B+",7,IF(P25="B",6,IF(P25="C",5,IF(P25="P",4,0))))))),0))*R25+(IFERROR(IF(S25="O",10,IF(S25="A+",9,IF(S25="A",8,IF(S25="B+",7,IF(S25="B",6,IF(S25="C",5,IF(S25="P",4,0))))))),0))*U25)/SUM(F25,I25,L25,O25,R25,U25),2),0) -> 0
A26: 18 | F26: =F7 -> 4 | I26: =I7 -> 4 | L26: =L7 -> 4 | O26: =O7 -> 4 | R26: =R7 -> 4 | U26: =U7 -> 4 | V26: =IFERROR(ROUND(((IFERROR(IF(D26="O",10,IF(D26="A+",9,IF(D26="A",8,IF(D26="B+",7,IF(D26="B",6,IF(D26="C",5,IF(D26="P",4,0))))))),0))*F26+(IFERROR(IF(G26="O",10,IF(G26="A+",9,IF(G26="A",8,IF(G26="B+",7,IF(G26="B",6,IF(G26="C",5,IF(G26="P",4,0))))))),0))*I26+(IFERROR(IF(J26="O",10,IF(J26="A+",9,IF(J26="A",8,IF(J26="B+",7,IF(J26="B",6,IF(J26="C",5,IF(J26="P",4,0))))))),0))*L26+(IFERROR(IF(M26="O",10,IF(M26="A+",9,IF(M26="A",8,IF(M26="B+",7,IF(M26="B",6,IF(M26="C",5,IF(M26="P",4,0))))))),0))*O26+(IFERROR(IF(P26="O",10,IF(P26="A+",9,IF(P26="A",8,IF(P26="B+",7,IF(P26="B",6,IF(P26="C",5,IF(P26="P",4,0))))))),0))*R26+(IFERROR(IF(S26="O",10,IF(S26="A+",9,IF(S26="A",8,IF(S26="B+",7,IF(S26="B",6,IF(S26="C",5,IF(S26="P",4,0))))))),0))*U26)/SUM(F26,I26,L26,O26,R26,U26),2),0) -> 0
A27: 19 | F27: =F7 -> 4 | I27: =I7 -> 4 | L27: =L7 -> 4 | O27: =O7 -> 4 | R27: =R7 -> 4 | U27: =U7 -> 4 | V27: =IFERROR(ROUND(((IFERROR(IF(D27="O",10,IF(D27="A+",9,IF(D27="A",8,IF(D27="B+",7,IF(D27="B",6,IF(D27="C",5,IF(D27="P",4,0))))))),0))*F27+(IFERROR(IF(G27="O",10,IF(G27="A+",9,IF(G27="A",8,IF(G27="B+",7,IF(G27="B",6,IF(G27="C",5,IF(G27="P",4,0))))))),0))*I27+(IFERROR(IF(J27="O",10,IF(J27="A+",9,IF(J27="A",8,IF(J27="B+",7,IF(J27="B",6,IF(J27="C",5,IF(J27="P",4,0))))))),0))*L27+(IFERROR(IF(M27="O",10,IF(M27="A+",9,IF(M27="A",8,IF(M27="B+",7,IF(M27="B",6,IF(M27="C",5,IF(M27="P",4,0))))))),0))*O27+(IFERROR(IF(P27="O",10,IF(P27="A+",9,IF(P27="A",8,IF(P27="B+",7,IF(P27="B",6,IF(P27="C",5,IF(P27="P",4,0))))))),0))*R27+(IFERROR(IF(S27="O",10,IF(S27="A+",9,IF(S27="A",8,IF(S27="B+",7,IF(S27="B",6,IF(S27="C",5,IF(S27="P",4,0))))))),0))*U27)/SUM(F27,I27,L27,O27,R27,U27),2),0) -> 0
A28: 20 | F28: =F7 -> 4 | I28: =I7 -> 4 | L28: =L7 -> 4 | O28: =O7 -> 4 | R28: =R7 -> 4 | U28: =U7 -> 4 | V28: =IFERROR(ROUND(((IFERROR(IF(D28="O",10,IF(D28="A+",9,IF(D28="A",8,IF(D28="B+",7,IF(D28="B",6,IF(D28="C",5,IF(D28="P",4,0))))))),0))*F28+(IFERROR(IF(G28="O",10,IF(G28="A+",9,IF(G28="A",8,IF(G28="B+",7,IF(G28="B",6,IF(G28="C",5,IF(G28="P",4,0))))))),0))*I28+(IFERROR(IF(J28="O",10,IF(J28="A+",9,IF(J28="A",8,IF(J28="B+",7,IF(J28="B",6,IF(J28="C",5,IF(J28="P",4,0))))))),0))*L28+(IFERROR(IF(M28="O",10,IF(M28="A+",9,IF(M28="A",8,IF(M28="B+",7,IF(M28="B",6,IF(M28="C",5,IF(M28="P",4,0))))))),0))*O28+(IFERROR(IF(P28="O",10,IF(P28="A+",9,IF(P28="A",8,IF(P28="B+",7,IF(P28="B",6,IF(P28="C",5,IF(P28="P",4,0))))))),0))*R28+(IFERROR(IF(S28="O",10,IF(S28="A+",9,IF(S28="A",8,IF(S28="B+",7,IF(S28="B",6,IF(S28="C",5,IF(S28="P",4,0))))))),0))*U28)/SUM(F28,I28,L28,O28,R28,U28),2),0) -> 0
A29: 21 | F29: =F7 -> 4 | I29: =I7 -> 4 | L29: =L7 -> 4 | O29: =O7 -> 4 | R29: =R7 -> 4 | U29: =U7 -> 4 | V29: =IFERROR(ROUND(((IFERROR(IF(D29="O",10,IF(D29="A+",9,IF(D29="A",8,IF(D29="B+",7,IF(D29="B",6,IF(D29="C",5,IF(D29="P",4,0))))))),0))*F29+(IFERROR(IF(G29="O",10,IF(G29="A+",9,IF(G29="A",8,IF(G29="B+",7,IF(G29="B",6,IF(G29="C",5,IF(G29="P",4,0))))))),0))*I29+(IFERROR(IF(J29="O",10,IF(J29="A+",9,IF(J29="A",8,IF(J29="B+",7,IF(J29="B",6,IF(J29="C",5,IF(J29="P",4,0))))))),0))*L29+(IFERROR(IF(M29="O",10,IF(M29="A+",9,IF(M29="A",8,IF(M29="B+",7,IF(M29="B",6,IF(M29="C",5,IF(M29="P",4,0))))))),0))*O29+(IFERROR(IF(P29="O",10,IF(P29="A+",9,IF(P29="A",8,IF(P29="B+",7,IF(P29="B",6,IF(P29="C",5,IF(P29="P",4,0))))))),0))*R29+(IFERROR(IF(S29="O",10,IF(S29="A+",9,IF(S29="A",8,IF(S29="B+",7,IF(S29="B",6,IF(S29="C",5,IF(S29="P",4,0))))))),0))*U29)/SUM(F29,I29,L29,O29,R29,U29),2),0) -> 0
A30: 22 | F30: =F7 -> 4 | I30: =I7 -> 4 | L30: =L7 -> 4 | O30: =O7 -> 4 | R30: =R7 -> 4 | U30: =U7 -> 4 | V30: =IFERROR(ROUND(((IFERROR(IF(D30="O",10,IF(D30="A+",9,IF(D30="A",8,IF(D30="B+",7,IF(D30="B",6,IF(D30="C",5,IF(D30="P",4,0))))))),0))*F30+(IFERROR(IF(G30="O",10,IF(G30="A+",9,IF(G30="A",8,IF(G30="B+",7,IF(G30="B",6,IF(G30="C",5,IF(G30="P",4,0))))))),0))*I30+(IFERROR(IF(J30="O",10,IF(J30="A+",9,IF(J30="A",8,IF(J30="B+",7,IF(J30="B",6,IF(J30="C",5,IF(J30="P",4,0))))))),0))*L30+(IFERROR(IF(M30="O",10,IF(M30="A+",9,IF(M30="A",8,IF(M30="B+",7,IF(M30="B",6,IF(M30="C",5,IF(M30="P",4,0))))))),0))*O30+(IFERROR(IF(P30="O",10,IF(P30="A+",9,IF(P30="A",8,IF(P30="B+",7,IF(P30="B",6,IF(P30="C",5,IF(P30="P",4,0))))))),0))*R30+(IFERROR(IF(S30="O",10,IF(S30="A+",9,IF(S30="A",8,IF(S30="B+",7,IF(S30="B",6,IF(S30="C",5,IF(S30="P",4,0))))))),0))*U30)/SUM(F30,I30,L30,O30,R30,U30),2),0) -> 0
A31: 23 | F31: =F7 -> 4 | I31: =I7 -> 4 | L31: =L7 -> 4 | O31: =O7 -> 4 | R31: =R7 -> 4 | U31: =U7 -> 4 | V31: =IFERROR(ROUND(((IFERROR(IF(D31="O",10,IF(D31="A+",9,IF(D31="A",8,IF(D31="B+",7,IF(D31="B",6,IF(D31="C",5,IF(D31="P",4,0))))))),0))*F31+(IFERROR(IF(G31="O",10,IF(G31="A+",9,IF(G31="A",8,IF(G31="B+",7,IF(G31="B",6,IF(G31="C",5,IF(G31="P",4,0))))))),0))*I31+(IFERROR(IF(J31="O",10,IF(J31="A+",9,IF(J31="A",8,IF(J31="B+",7,IF(J31="B",6,IF(J31="C",5,IF(J31="P",4,0))))))),0))*L31+(IFERROR(IF(M31="O",10,IF(M31="A+",9,IF(M31="A",8,IF(M31="B+",7,IF(M31="B",6,IF(M31="C",5,IF(M31="P",4,0))))))),0))*O31+(IFERROR(IF(P31="O",10,IF(P31="A+",9,IF(P31="A",8,IF(P31="B+",7,IF(P31="B",6,IF(P31="C",5,IF(P31="P",4,0))))))),0))*R31+(IFERROR(IF(S31="O",10,IF(S31="A+",9,IF(S31="A",8,IF(S31="B+",7,IF(S31="B",6,IF(S31="C",5,IF(S31="P",4,0))))))),0))*U31)/SUM(F31,I31,L31,O31,R31,U31),2),0) -> 0
A32: 24 | F32: =F7 -> 4 | I32: =I7 -> 4 | L32: =L7 -> 4 | O32: =O7 -> 4 | R32: =R7 -> 4 | U32: =U7 -> 4 | V32: =IFERROR(ROUND(((IFERROR(IF(D32="O",10,IF(D32="A+",9,IF(D32="A",8,IF(D32="B+",7,IF(D32="B",6,IF(D32="C",5,IF(D32="P",4,0))))))),0))*F32+(IFERROR(IF(G32="O",10,IF(G32="A+",9,IF(G32="A",8,IF(G32="B+",7,IF(G32="B",6,IF(G32="C",5,IF(G32="P",4,0))))))),0))*I32+(IFERROR(IF(J32="O",10,IF(J32="A+",9,IF(J32="A",8,IF(J32="B+",7,IF(J32="B",6,IF(J32="C",5,IF(J32="P",4,0))))))),0))*L32+(IFERROR(IF(M32="O",10,IF(M32="A+",9,IF(M32="A",8,IF(M32="B+",7,IF(M32="B",6,IF(M32="C",5,IF(M32="P",4,0))))))),0))*O32+(IFERROR(IF(P32="O",10,IF(P32="A+",9,IF(P32="A",8,IF(P32="B+",7,IF(P32="B",6,IF(P32="C",5,IF(P32="P",4,0))))))),0))*R32+(IFERROR(IF(S32="O",10,IF(S32="A+",9,IF(S32="A",8,IF(S32="B+",7,IF(S32="B",6,IF(S32="C",5,IF(S32="P",4,0))))))),0))*U32)/SUM(F32,I32,L32,O32,R32,U32),2),0) -> 0
A33: 25 | F33: =F7 -> 4 | I33: =I7 -> 4 | L33: =L7 -> 4 | O33: =O7 -> 4 | R33: =R7 -> 4 | U33: =U7 -> 4 | V33: =IFERROR(ROUND(((IFERROR(IF(D33="O",10,IF(D33="A+",9,IF(D33="A",8,IF(D33="B+",7,IF(D33="B",6,IF(D33="C",5,IF(D33="P",4,0))))))),0))*F33+(IFERROR(IF(G33="O",10,IF(G33="A+",9,IF(G33="A",8,IF(G33="B+",7,IF(G33="B",6,IF(G33="C",5,IF(G33="P",4,0))))))),0))*I33+(IFERROR(IF(J33="O",10,IF(J33="A+",9,IF(J33="A",8,IF(J33="B+",7,IF(J33="B",6,IF(J33="C",5,IF(J33="P",4,0))))))),0))*L33+(IFERROR(IF(M33="O",10,IF(M33="A+",9,IF(M33="A",8,IF(M33="B+",7,IF(M33="B",6,IF(M33="C",5,IF(M33="P",4,0))))))),0))*O33+(IFERROR(IF(P33="O",10,IF(P33="A+",9,IF(P33="A",8,IF(P33="B+",7,IF(P33="B",6,IF(P33="C",5,IF(P33="P",4,0))))))),0))*R33+(IFERROR(IF(S33="O",10,IF(S33="A+",9,IF(S33="A",8,IF(S33="B+",7,IF(S33="B",6,IF(S33="C",5,IF(S33="P",4,0))))))),0))*U33)/SUM(F33,I33,L33,O33,R33,U33),2),0) -> 0
A34: 26 | F34: =F7 -> 4 | I34: =I7 -> 4 | L34: =L7 -> 4 | O34: =O7 -> 4 | R34: =R7 -> 4 | U34: =U7 -> 4 | V34: =IFERROR(ROUND(((IFERROR(IF(D34="O",10,IF(D34="A+",9,IF(D34="A",8,IF(D34="B+",7,IF(D34="B",6,IF(D34="C",5,IF(D34="P",4,0))))))),0))*F34+(IFERROR(IF(G34="O",10,IF(G34="A+",9,IF(G34="A",8,IF(G34="B+",7,IF(G34="B",6,IF(G34="C",5,IF(G34="P",4,0))))))),0))*I34+(IFERROR(IF(J34="O",10,IF(J34="A+",9,IF(J34="A",8,IF(J34="B+",7,IF(J34="B",6,IF(J34="C",5,IF(J34="P",4,0))))))),0))*L34+(IFERROR(IF(M34="O",10,IF(M34="A+",9,IF(M34="A",8,IF(M34="B+",7,IF(M34="B",6,IF(M34="C",5,IF(M34="P",4,0))))))),0))*O34+(IFERROR(IF(P34="O",10,IF(P34="A+",9,IF(P34="A",8,IF(P34="B+",7,IF(P34="B",6,IF(P34="C",5,IF(P34="P",4,0))))))),0))*R34+(IFERROR(IF(S34="O",10,IF(S34="A+",9,IF(S34="A",8,IF(S34="B+",7,IF(S34="B",6,IF(S34="C",5,IF(S34="P",4,0))))))),0))*U34)/SUM(F34,I34,L34,O34,R34,U34),2),0) -> 0
A35: 27 | F35: =F7 -> 4 | I35: =I7 -> 4 | L35: =L7 -> 4 | O35: =O7 -> 4 | R35: =R7 -> 4 | U35: =U7 -> 4 | V35: =IFERROR(ROUND(((IFERROR(IF(D35="O",10,IF(D35="A+",9,IF(D35="A",8,IF(D35="B+",7,IF(D35="B",6,IF(D35="C",5,IF(D35="P",4,0))))))),0))*F35+(IFERROR(IF(G35="O",10,IF(G35="A+",9,IF(G35="A",8,IF(G35="B+",7,IF(G35="B",6,IF(G35="C",5,IF(G35="P",4,0))))))),0))*I35+(IFERROR(IF(J35="O",10,IF(J35="A+",9,IF(J35="A",8,IF(J35="B+",7,IF(J35="B",6,IF(J35="C",5,IF(J35="P",4,0))))))),0))*L35+(IFERROR(IF(M35="O",10,IF(M35="A+",9,IF(M35="A",8,IF(M35="B+",7,IF(M35="B",6,IF(M35="C",5,IF(M35="P",4,0))))))),0))*O35+(IFERROR(IF(P35="O",10,IF(P35="A+",9,IF(P35="A",8,IF(P35="B+",7,IF(P35="B",6,IF(P35="C",5,IF(P35="P",4,0))))))),0))*R35+(IFERROR(IF(S35="O",10,IF(S35="A+",9,IF(S35="A",8,IF(S35="B+",7,IF(S35="B",6,IF(S35="C",5,IF(S35="P",4,0))))))),0))*U35)/SUM(F35,I35,L35,O35,R35,U35),2),0) -> 0
A36: 28 | F36: =F7 -> 4 | I36: =I7 -> 4 | L36: =L7 -> 4 | O36: =O7 -> 4 | R36: =R7 -> 4 | U36: =U7 -> 4 | V36: =IFERROR(ROUND(((IFERROR(IF(D36="O",10,IF(D36="A+",9,IF(D36="A",8,IF(D36="B+",7,IF(D36="B",6,IF(D36="C",5,IF(D36="P",4,0))))))),0))*F36+(IFERROR(IF(G36="O",10,IF(G36="A+",9,IF(G36="A",8,IF(G36="B+",7,IF(G36="B",6,IF(G36="C",5,IF(G36="P",4,0))))))),0))*I36+(IFERROR(IF(J36="O",10,IF(J36="A+",9,IF(J36="A",8,IF(J36="B+",7,IF(J36="B",6,IF(J36="C",5,IF(J36="P",4,0))))))),0))*L36+(IFERROR(IF(M36="O",10,IF(M36="A+",9,IF(M36="A",8,IF(M36="B+",7,IF(M36="B",6,IF(M36="C",5,IF(M36="P",4,0))))))),0))*O36+(IFERROR(IF(P36="O",10,IF(P36="A+",9,IF(P36="A",8,IF(P36="B+",7,IF(P36="B",6,IF(P36="C",5,IF(P36="P",4,0))))))),0))*R36+(IFERROR(IF(S36="O",10,IF(S36="A+",9,IF(S36="A",8,IF(S36="B+",7,IF(S36="B",6,IF(S36="C",5,IF(S36="P",4,0))))))),0))*U36)/SUM(F36,I36,L36,O36,R36,U36),2),0) -> 0
A37: 29 | F37: =F7 -> 4 | I37: =I7 -> 4 | L37: =L7 -> 4 | O37: =O7 -> 4 | R37: =R7 -> 4 | U37: =U7 -> 4 | V37: =IFERROR(ROUND(((IFERROR(IF(D37="O",10,IF(D37="A+",9,IF(D37="A",8,IF(D37="B+",7,IF(D37="B",6,IF(D37="C",5,IF(D37="P",4,0))))))),0))*F37+(IFERROR(IF(G37="O",10,IF(G37="A+",9,IF(G37="A",8,IF(G37="B+",7,IF(G37="B",6,IF(G37="C",5,IF(G37="P",4,0))))))),0))*I37+(IFERROR(IF(J37="O",10,IF(J37="A+",9,IF(J37="A",8,IF(J37="B+",7,IF(J37="B",6,IF(J37="C",5,IF(J37="P",4,0))))))),0))*L37+(IFERROR(IF(M37="O",10,IF(M37="A+",9,IF(M37="A",8,IF(M37="B+",7,IF(M37="B",6,IF(M37="C",5,IF(M37="P",4,0))))))),0))*O37+(IFERROR(IF(P37="O",10,IF(P37="A+",9,IF(P37="A",8,IF(P37="B+",7,IF(P37="B",6,IF(P37="C",5,IF(P37="P",4,0))))))),0))*R37+(IFERROR(IF(S37="O",10,IF(S37="A+",9,IF(S37="A",8,IF(S37="B+",7,IF(S37="B",6,IF(S37="C",5,IF(S37="P",4,0))))))),0))*U37)/SUM(F37,I37,L37,O37,R37,U37),2),0) -> 0
A38: 30 | F38: =F7 -> 4 | I38: =I7 -> 4 | L38: =L7 -> 4 | O38: =O7 -> 4 | R38: =R7 -> 4 | U38: =U7 -> 4 | V38: =IFERROR(ROUND(((IFERROR(IF(D38="O",10,IF(D38="A+",9,IF(D38="A",8,IF(D38="B+",7,IF(D38="B",6,IF(D38="C",5,IF(D38="P",4,0))))))),0))*F38+(IFERROR(IF(G38="O",10,IF(G38="A+",9,IF(G38="A",8,IF(G38="B+",7,IF(G38="B",6,IF(G38="C",5,IF(G38="P",4,0))))))),0))*I38+(IFERROR(IF(J38="O",10,IF(J38="A+",9,IF(J38="A",8,IF(J38="B+",7,IF(J38="B",6,IF(J38="C",5,IF(J38="P",4,0))))))),0))*L38+(IFERROR(IF(M38="O",10,IF(M38="A+",9,IF(M38="A",8,IF(M38="B+",7,IF(M38="B",6,IF(M38="C",5,IF(M38="P",4,0))))))),0))*O38+(IFERROR(IF(P38="O",10,IF(P38="A+",9,IF(P38="A",8,IF(P38="B+",7,IF(P38="B",6,IF(P38="C",5,IF(P38="P",4,0))))))),0))*R38+(IFERROR(IF(S38="O",10,IF(S38="A+",9,IF(S38="A",8,IF(S38="B+",7,IF(S38="B",6,IF(S38="C",5,IF(S38="P",4,0))))))),0))*U38)/SUM(F38,I38,L38,O38,R38,U38),2),0) -> 0
A39: 31 | F39: =F7 -> 4 | I39: =I7 -> 4 | L39: =L7 -> 4 | O39: =O7 -> 4 | R39: =R7 -> 4 | U39: =U7 -> 4 | V39: =IFERROR(ROUND(((IFERROR(IF(D39="O",10,IF(D39="A+",9,IF(D39="A",8,IF(D39="B+",7,IF(D39="B",6,IF(D39="C",5,IF(D39="P",4,0))))))),0))*F39+(IFERROR(IF(G39="O",10,IF(G39="A+",9,IF(G39="A",8,IF(G39="B+",7,IF(G39="B",6,IF(G39="C",5,IF(G39="P",4,0))))))),0))*I39+(IFERROR(IF(J39="O",10,IF(J39="A+",9,IF(J39="A",8,IF(J39="B+",7,IF(J39="B",6,IF(J39="C",5,IF(J39="P",4,0))))))),0))*L39+(IFERROR(IF(M39="O",10,IF(M39="A+",9,IF(M39="A",8,IF(M39="B+",7,IF(M39="B",6,IF(M39="C",5,IF(M39="P",4,0))))))),0))*O39+(IFERROR(IF(P39="O",10,IF(P39="A+",9,IF(P39="A",8,IF(P39="B+",7,IF(P39="B",6,IF(P39="C",5,IF(P39="P",4,0))))))),0))*R39+(IFERROR(IF(S39="O",10,IF(S39="A+",9,IF(S39="A",8,IF(S39="B+",7,IF(S39="B",6,IF(S39="C",5,IF(S39="P",4,0))))))),0))*U39)/SUM(F39,I39,L39,O39,R39,U39),2),0) -> 0
A40: 32 | F40: =F7 -> 4 | I40: =I7 -> 4 | L40: =L7 -> 4 | O40: =O7 -> 4 | R40: =R7 -> 4 | U40: =U7 -> 4 | V40: =IFERROR(ROUND(((IFERROR(IF(D40="O",10,IF(D40="A+",9,IF(D40="A",8,IF(D40="B+",7,IF(D40="B",6,IF(D40="C",5,IF(D40="P",4,0))))))),0))*F40+(IFERROR(IF(G40="O",10,IF(G40="A+",9,IF(G40="A",8,IF(G40="B+",7,IF(G40="B",6,IF(G40="C",5,IF(G40="P",4,0))))))),0))*I40+(IFERROR(IF(J40="O",10,IF(J40="A+",9,IF(J40="A",8,IF(J40="B+",7,IF(J40="B",6,IF(J40="C",5,IF(J40="P",4,0))))))),0))*L40+(IFERROR(IF(M40="O",10,IF(M40="A+",9,IF(M40="A",8,IF(M40="B+",7,IF(M40="B",6,IF(M40="C",5,IF(M40="P",4,0))))))),0))*O40+(IFERROR(IF(P40="O",10,IF(P40="A+",9,IF(P40="A",8,IF(P40="B+",7,IF(P40="B",6,IF(P40="C",5,IF(P40="P",4,0))))))),0))*R40+(IFERROR(IF(S40="O",10,IF(S40="A+",9,IF(S40="A",8,IF(S40="B+",7,IF(S40="B",6,IF(S40="C",5,IF(S40="P",4,0))))))),0))*U40)/SUM(F40,I40,L40,O40,R40,U40),2),0) -> 0
A41: 33 | F41: =F7 -> 4 | I41: =I7 -> 4 | L41: =L7 -> 4 | O41: =O7 -> 4 | R41: =R7 -> 4 | U41: =U7 -> 4 | V41: =IFERROR(ROUND(((IFERROR(IF(D41="O",10,IF(D41="A+",9,IF(D41="A",8,IF(D41="B+",7,IF(D41="B",6,IF(D41="C",5,IF(D41="P",4,0))))))),0))*F41+(IFERROR(IF(G41="O",10,IF(G41="A+",9,IF(G41="A",8,IF(G41="B+",7,IF(G41="B",6,IF(G41="C",5,IF(G41="P",4,0))))))),0))*I41+(IFERROR(IF(J41="O",10,IF(J41="A+",9,IF(J41="A",8,IF(J41="B+",7,IF(J41="B",6,IF(J41="C",5,IF(J41="P",4,0))))))),0))*L41+(IFERROR(IF(M41="O",10,IF(M41="A+",9,IF(M41="A",8,IF(M41="B+",7,IF(M41="B",6,IF(M41="C",5,IF(M41="P",4,0))))))),0))*O41+(IFERROR(IF(P41="O",10,IF(P41="A+",9,IF(P41="A",8,IF(P41="B+",7,IF(P41="B",6,IF(P41="C",5,IF(P41="P",4,0))))))),0))*R41+(IFERROR(IF(S41="O",10,IF(S41="A+",9,IF(S41="A",8,IF(S41="B+",7,IF(S41="B",6,IF(S41="C",5,IF(S41="P",4,0))))))),0))*U41)/SUM(F41,I41,L41,O41,R41,U41),2),0) -> 0
...

Sheet Subject-Wise Summary
A1: SEMESTER END EXAMINATION — SUBJECT-WISE RESULT SUMMARY
A2: Department: | C2: Academic Year: | F2: Semester:
A3: Programme: | C3: Branch: | E3: Class: | G3: Section:
A5: Si. No | B5: Name of the Course | C5: Course Code | D5: Course Instructor | E5: Section | F5: No. of Students on Rolls | G5: No. of Students Registered | H5: No. of Students Absent | I5: No. of Students Passed | J5: No. of Students Failed | K5: Pass % (of Registered) | L5: Signature of Course Instructor
A6: 1 | B6: Course Name 1 | C6: SUBJ1 | E6: A | J6: =IFERROR(G6-H6-I6,0) -> 0 | K6: =IFERROR(IF(G6=0,0,ROUND(I6/G6*100,1)),0) -> 0
A7: 2 | B7: Course Name 2 | C7: SUBJ2 | E7: A | J7: =IFERROR(G7-H7-I7,0) -> 0 | K7: =IFERROR(IF(G7=0,0,ROUND(I7/G7*100,1)),0) -> 0
A8: 3 | B8: Course Name 3 | C8: SUBJ3 | E8: A | J8: =IFERROR(G8-H8-I8,0) -> 0 | K8: =IFERROR(IF(G8=0,0,ROUND(I8/G8*100,1)),0) -> 0
A9: 4 | B9: Course Name 4 | C9: SUBJ4 | E9: A | J9: =IFERROR(G9-H9-I9,0) -> 0 | K9: =IFERROR(IF(G9=0,0,ROUND(I9/G9*100,1)),0) -> 0
A10: 5 | B10: Course Name 5 | C10: SUBJ5 | E10: A | J10: =IFERROR(G10-H10-I10,0) -> 0 | K10: =IFERROR(IF(G10=0,0,ROUND(I10/G10*100,1)),0) -> 0
A11: 6 | B11: Course Name 6 | C11: SUBJ6 | E11: A | J11: =IFERROR(G11-H11-I11,0) -> 0 | K11: =IFERROR(IF(G11=0,0,ROUND(I11/G11*100,1)),0) -> 0
A12: OVERALL | F12: =SUM(F6:F11) -> 0 | G12: =SUM(G6:G11) -> 0 | H12: =SUM(H6:H11) -> 0 | I12: =SUM(I6:I11) -> 0 | J12: =SUM(J6:J11) -> 0 | K12: =IFERROR(ROUND(I12/G12*100,1),0) -> 0
A14: Dept. Exam In-charge | D14: Signature of HOD | I14: PRINCIPAL

Sheet Overall Pass Analysis
A1: OVERALL PASS ANALYSIS — ALL SUBJECTS
A2: Department: | C2: Academic Year: | F2: Semester:
A3: Programme: | C3: Branch: | E3: Class:
A5: Total No. of Students Registered: | D5: Total No. of Students All Subjects Passed: | G5: Overall Pass Percentage:
A7: Si. No | B7: Subject Name | C7: Course Code | D7: Registered | E7: Passed | F7: Failed | G7: Pass %
A8: 1 | B8: ='Subject-Wise Summary'!B6 -> Course Name 1 | C8: ='Subject-Wise Summary'!C6 -> SUBJ1 | D8: ='Subject-Wise Summary'!G6 -> 0 | E8: ='Subject-Wise Summary'!I6 -> 0 | F8: ='Subject-Wise Summary'!J6 -> 0 | G8: ='Subject-Wise Summary'!K6 -> 0
A9: 2 | B9: ='Subject-Wise Summary'!B7 -> Course Name 2 | C9: ='Subject-Wise Summary'!C7 -> SUBJ2 | D9: ='Subject-Wise Summary'!G7 -> 0 | E9: ='Subject-Wise Summary'!I7 -> 0 | F9: ='Subject-Wise Summary'!J7 -> 0 | G9: ='Subject-Wise Summary'!K7 -> 0
A10: 3 | B10: ='Subject-Wise Summary'!B8 -> Course Name 3 | C10: ='Subject-Wise Summary'!C8 -> SUBJ3 | D10: ='Subject-Wise Summary'!G8 -> 0 | E10: ='Subject-Wise Summary'!I8 -> 0 | F10: ='Subject-Wise Summary'!J8 -> 0 | G10: ='Subject-Wise Summary'!K8 -> 0
A11: 4 | B11: ='Subject-Wise Summary'!B9 -> Course Name 4 | C11: ='Subject-Wise Summary'!C9 -> SUBJ4 | D11: ='Subject-Wise Summary'!G9 -> 0 | E11: ='Subject-Wise Summary'!I9 -> 0 | F11: ='Subject-Wise Summary'!J9 -> 0 | G11: ='Subject-Wise Summary'!K9 -> 0
A12: 5 | B12: ='Subject-Wise Summary'!B10 -> Course Name 5 | C12: ='Subject-Wise Summary'!C10 -> SUBJ5 | D12: ='Subject-Wise Summary'!G10 -> 0 | E12: ='Subject-Wise Summary'!I10 -> 0 | F12: ='Subject-Wise Summary'!J10 -> 0 | G12: ='Subject-Wise Summary'!K10 -> 0
A13: 6 | B13: ='Subject-Wise Summary'!B11 -> Course Name 6 | C13: ='Subject-Wise Summary'!C11 -> SUBJ6 | D13: ='Subject-Wise Summary'!G11 -> 0 | E13: ='Subject-Wise Summary'!I11 -> 0 | F13: ='Subject-Wise Summary'!J11 -> 0 | G13: ='Subject-Wise Summary'!K11 -> 0
A14: TOTAL / AVERAGE | D14: =SUM(D8:D13) -> 0 | E14: =SUM(E8:E13) -> 0 | F14: =SUM(F8:F13) -> 0 | G14: =IFERROR(ROUND(E14/D14*100,1),0) -> 0
A46: Dept. Exam In-charge | C46: Signature of HOD | F46: PRINCIPAL

Sheet Grade Distribution
A1: GRADE DISTRIBUTION & SGPA BAND ANALYSIS
A2: Department: | C2: Academic Year: | F2: Semester:
A4: SGPA BAND DISTRIBUTION
A5: SGPA Range | B5: No. of Students | C5: Percentage % | D5: Remarks
A6: 10.0 (O) | B6: =COUNTIF('Student-Wise Result'!V9:V68,"=10") -> 0 | C6: =IFERROR(ROUND(B6/60*100,1),0) -> 0 | D6: Outstanding
A7: 9.0–9.9 (A+) | B7: =COUNTIFS('Student-Wise Result'!V9:V68,">8.0",'Student-Wise Result'!V9:V68,"<=9.99") -> 0 | C7: =IFERROR(ROUND(B7/60*100,1),0) -> 0 | D7: Excellent
A8: 8.0–8.9 (A) | B8: =COUNTIFS('Student-Wise Result'!V9:V68,">7.0",'Student-Wise Result'!V9:V68,"<=8.99") -> 0 | C8: =IFERROR(ROUND(B8/60*100,1),0) -> 0 | D8: Very Good
A9: 7.0–7.9 (B+) | B9: =COUNTIFS('Student-Wise Result'!V9:V68,">6.0",'Student-Wise Result'!V9:V68,"<=7.99") -> 0 | C9: =IFERROR(ROUND(B9/60*100,1),0) -> 0 | D9: Good
A10: 6.0–6.9 (B) | B10: =COUNTIFS('Student-Wise Result'!V9:V68,">5.0",'Student-Wise Result'!V9:V68,"<=6.99") -> 0 | C10: =IFERROR(ROUND(B10/60*100,1),0) -> 0 | D10: Above Average
A11: 5.0–5.9 (C) | B11: =COUNTIFS('Student-Wise Result'!V9:V68,">4.0",'Student-Wise Result'!V9:V68,"<=5.99") -> 0 | C11: =IFERROR(ROUND(B11/60*100,1),0) -> 0 | D11: Average
A12: 4.0–4.9 (P) | B12: =COUNTIFS('Student-Wise Result'!V9:V68,">3.0",'Student-Wise Result'!V9:V68,"<=4.99") -> 0 | C12: =IFERROR(ROUND(B12/60*100,1),0) -> 0 | D12: Pass
A13: < 4.0 (F) | B13: ='Student-Wise Result'!V76 -> 0 | C13: =IFERROR(ROUND(B13/60*100,1),0) -> 0 | D13: Fail
A14: TOTAL | B14: =SUM(B6:B13) -> 0 | C14: =IFERROR(ROUND(B14/60*100,1),0) -> 0

Sheet Instructions
A1: INSTRUCTIONS FOR USING THIS WORKBOOK
A2: STEP-BY-STEP INSTRUCTIONS
A3: 1. | B3: Sheet 1 'Student-Wise Result': Enter Reg. No, Student Name, and YELLOW cells — Grade (O/A+/A/B+/B/C/P/F) and Marks for each course per student.
A4: 2. | B4: Do NOT enter anything in LIGHT BLUE cells — these are auto-calculated (SGPA, Grade Counts, Pass%, etc.).
A5: 3. | B5: SGPA auto-calculates using: SGPA = Σ(Grade Points × Credits) / Σ(Credits). Enter CGPA manually.
A6: 4. | B6: Grade point scale: O=10, A+=9, A=8, B+=7, B=6, C=5, P=4, F=0. Enter grades exactly as listed.
A7: 5. | B7: Credits per course: Editable in Row 7. Default is 4. Change once — all student rows update automatically.
A8: 6. | B8: Sheet 2 'Subject-Wise Summary': Enter Enrolled, Registered, Absent, Passed counts per subject. Failed and Pass% auto-calculate.
A9: 7. | B9: Sheet 3 'Overall Pass Analysis': Pulls data from Subject-Wise sheet automatically. Two bar charts auto-update.
A10: 8. | B10: Sheet 4 'Grade Distribution': Pulls SGPA data from Student-Wise sheet and shows band distribution with chart.
A11: 9. | B11: To add more students: Insert rows ABOVE the last student row (before Grade Distribution rows).
A12: 10. | B12: All signature cells are editable blue fields at the bottom of each sheet.
A14: COLOUR CODING GUIDE
B15: YELLOW = Editable input cells (enter data here)
B16: LIGHT BLUE = Auto-calculated (do NOT edit)
B17: LIGHT GRAY = Alternating row shading
B18: LIGHT GREEN = Positive metrics (Passed, Pass%)
B19: LIGHT ORANGE = Negative metrics (Failed)
B20: SKY BLUE = Signature / information fields
